
<mujoco model="Fish">
    <option gravity="0 0 0" density="1000" viscosity="0.0013" integrator="implicit" timestep="0.001" iterations="100" solver="Newton" tolerance="1e-15" o_solimp="0 0.01 0.01 0.1 2">
        <flag contact="disable"/>
        <!-- <flag override="enable"/> -->
    </option>

    <visual>
        <map force="0.1" zfar="30"/>
        <rgba haze="0.15 0.25 0.35 1"/>
        <global offwidth="2560" offheight="1440" elevation="-20" azimuth="120"/>
    </visual>

    <statistic center="0 0 0.7"/>

    <asset>
        <texture type="skybox" builtin="gradient" rgb1=".3 .5 .7" rgb2="0 0 0" width="32" height="512"/>
        <texture name="body" type="cube" builtin="flat" mark="cross" width="127" height="127" rgb1="0.8 0.6 0.4" rgb2="0.8 0.6 0.4" markrgb="1 1 1" random="0.01"/>
        <material name="body" texture="body" texuniform="true" rgba="0.8 0.6 .4 1"/>
        <texture name="grid" type="2d" builtin="checker" width="512" height="512" rgb1=".1 .2 .3" rgb2=".2 .3 .4"/>
        <material name="grid" texture="grid" texrepeat="1 1" texuniform="true" reflectance=".2"/>

        <mesh name="finTop" file="fish/finTop.obj"/>
        <mesh name="finTail" file="fish/finTail.obj"/>

        <texture name="acrylic" type="cube" builtin="flat" mark="cross" width="127" height="127" rgb1=".9 .9 .9" rgb2=".9 .9 .9" markrgb="1 1 1" random="0.01"/>
        <material name="acrylic" texture="acrylic" texuniform="true"/>

        <texture name="alu" type="cube" builtin="flat" mark="cross" width="127" height="127" rgb1=".7 .7 .7" rgb2=".7 .7 .7" markrgb="1 1 1" random="0.01"/>
        <material name="alu" texture="alu" texuniform="true"/>
        
        <texture name="marker" type="cube" builtin="flat" mark="cross" width="127" height="127" rgb1=".9 .4 .1" rgb2=".9 .4 .1" markrgb="1 1 1" random="0.01"/>
        <material name="marker" texture="marker" texuniform="true"/>
    </asset>

    <default>
        <joint type="hinge" pos="0 0 0" axis="0 0 1" limited="true" range="-80 80" stiffness="0.65" damping="0.0"/>
        <geom fluidcoef="0.1 0.1 0.1 2.0 1.0" condim="1"/>
        <tendon width="0.001" rgba=".9 .6 .5 1" stiffness="20000" damping="10"/>
    </default>


    <worldbody>
        <geom name="floor" pos="0 0 -0.2" size="0 0 .05" type="plane" material="grid"/>
        <light name="spotlight" mode="targetbodycom" target="fish" diffuse=".8 .8 .8" specular="0.3 0.3 0.3" pos="0 -6 4" cutoff="30"/>

        <body pos="0 0 0" name="fish">
            <joint name="headX" pos="0.02432519 0 0.00306519" type="slide" axis="1 0 0" stiffness="0" damping="0"/>
            <joint name="headY" pos="0.02432519 0 0.00306519" type="slide" axis="0 1 0" stiffness="0" damping="0"/>
            <joint name="headZ" pos="0.02432519 0 0.00306519" type="slide" axis="0 0 1" stiffness="100" damping="10"/>

            <joint name="headRollX" type="hinge" pos="0.02432519 0 0.00306519" axis="1 0 0" range="-180 180" stiffness="10" damping="1"/>
            <joint name="headRollY" type="hinge" pos="0.02432519 0 0.00306519" axis="0 1 0" range="-180 180" stiffness="10" damping="1"/>
            <joint name="headRollZ" type="hinge" pos="0.02432519 0 0.00306519" axis="0 0 1" range="-180 180" stiffness="0" damping="0"/>



            <site name="COM" pos="0.02432519 0 0.00306519" size="0.02" material="marker"/>

            <geom name="headPlate" type="box" pos="0 0 0" size="0.077 0.0025 0.05" material="acrylic" density="1180" fluidshape="ellipsoid"/>
            <geom name="headTopPlate" type="box" pos="0.01 0 0.0515" size="0.08 0.02 0.0015" material="acrylic" density="1180"/>
            <geom name="headTopElectric" type="box" pos="0.005 0 0.083" size="0.06 0.04 0.03" material="acrylic"/>
            <geom name="headAttachment" type="box" pos="0.1 0 0" size="0.023 0.015 0.05" material="alu" mass="0.08" fluidshape="ellipsoid"/>

            <geom name="body" type="box" pos="0.2005 0 0" size="0.0775 0.01 0.0525" material="alu" mass="0.6" fluidshape="ellipsoid"/>
            <geom name="body-joint0" type="box" pos="0.28150000000000003 0 0" size="0.0035 0.0005 0.0375" material="acrylic" mass="0.001" fluidshape="ellipsoid"/>

            <geom name="finTop" type="mesh" mesh="finTop" pos="0.26 0 0.04" material="acrylic" density="1180"/>

            <site name="marker0" pos="-0.077 0 0.05" size="0.005" material="marker"/>
            <site name="marker1" pos="0.065 0 0.05" size="0.005" material="marker"/>
            <site name="marker2" pos="0.1655 -0.0775 0.05" size="0.005" material="marker"/>
            <site name="marker3" pos="0.1655 0.0775 0.05" size="0.005" material="marker"/>
            <site name="bodyFin" pos="0.28 0 0.1" size="0.005" material="marker"/>


            <body pos="0.1655 0 0" name="motor">
                <joint name="motor" type="hinge" axis="0 1 0" pos="0 0 0" limited="false" stiffness="0" damping="0"/>
                
                <geom name="motorShaft" type="box" pos="0 0 0" size="0.0075 0.06 0.0075" material="acrylic"  mass="0.05" fluidshape="ellipsoid"/>
                <geom name="motorArmLeft" type="box" pos="0 -0.055 -0.01975" size="0.0075 0.005 0.01975" material="acrylic" density="1250" fluidshape="ellipsoid"/>
                <geom name="motorArmRight" type="box" pos="0 0.055 0.01975" size="0.0075 0.005 0.01975" material="acrylic" density="1250" fluidshape="ellipsoid"/>

                <site name="bodyLeft" pos="0 -0.055 -0.0345" size="0.005" material="acrylic"/>
                <site name="bodyRight" pos="0 0.055 0.0345" size="0.005" material="acrylic"/>
            </body>
            

            <body pos="0.28500000000000003 0 0">
                <geom name="joint0" type="cylinder" pos="0 0 0" size="0.002 0.0376" rgba=".9 .2 .2 1" mass="0"/>
                <joint name="joint0"/>
                <geom name="joint0-tail0" type="box" pos="0.0035 0 0" size="0.0035 0.0005 0.0375" rgba=".9 .9 .9 1" mass="0.001" fluidshape="ellipsoid"/>
                <geom name="tail0" type="box" pos="0.014499999999999999 0 0" size="0.0075 0.0015 0.05" rgba=".5 .7 .9 1" density="1250" fluidshape="ellipsoid"/>
                <site name="marker4" pos="0.014499999999999999 0 0.05" size="0.005" material="marker"/>

                <geom name="tail0left" type="box" pos="0.019 -0.02575 0" size="0.003 0.02425 0.007" rgba=".5 .7 .9 1" density="1250" fluidshape="ellipsoid"/>
                <geom name="tail0right" type="box" pos="0.019 0.02575 0" size="0.003 0.02425 0.007" rgba=".5 .7 .9 1" density="1250" fluidshape="ellipsoid"/>
                <site name="tail0left" pos="0.019 -0.045 0" size="0.004" rgba=".9 .6 .5 .5"/>
                <site name="tail0right" pos="0.019 0.045 0" size="0.004" rgba=".9 .6 .5 .5"/>

                <geom name="tail0-joint1" type="box" pos="0.02575 0 0" size="0.00375 0.0005 0.035" rgba=".9 .9 .9 1" mass="0.001" fluidshape="ellipsoid"/>

                <body pos="0.0295 0 0">
                    <geom name="joint1" type="cylinder" pos="0 0 0" size="0.002 0.0351" rgba=".6 .1 .1 1" mass="0"/>
                    <joint name="joint1"/>
                    <geom name="joint1-tail1" type="box" pos="0.00375 0 0" size="0.00375 0.0005 0.035" rgba=".9 .9 .9 1" mass="0.001" fluidshape="ellipsoid"/>
                    <geom name="tail1" type="box" pos="0.015 0 0" size="0.0075 0.0015 0.0475" rgba=".5 .7 .9 1" density="1250" fluidshape="ellipsoid"/>
                    <site name="marker5" pos="0.015 0 0.05" size="0.005" material="marker"/>

                    <geom name="tail1left" type="box" pos="0.0195 -0.02075 0" size="0.003 0.01925 0.007" rgba=".5 .7 .9 1" density="1250" fluidshape="ellipsoid"/>
                    <geom name="tail1right" type="box" pos="0.0195 0.02075 0" size="0.003 0.01925 0.007" rgba=".5 .7 .9 1" density="1250" fluidshape="ellipsoid"/>
                    <site name="tail1left" pos="0.0195 -0.035 0" size="0.004" rgba=".9 .6 .5 .5"/>
                    <site name="tail1right" pos="0.0195 0.035 0" size="0.004" rgba=".9 .6 .5 .5"/>

                    <geom name="tail1-joint2" type="box" pos="0.02675 0 0" size="0.00425 0.0005 0.0325" rgba=".9 .9 .9 1" mass="0.001" fluidshape="ellipsoid"/>

                    <body pos="0.031 0 0">
                        <geom name="joint2" type="cylinder" pos="0 0 0" size="0.002 0.0326" rgba=".6 .1 .1 1" mass="0"/>
                        <joint name="joint2"/>
                        <geom name="joint2-tail2" type="box" pos="0.00425 0 0" size="0.00425 0.0005 0.0325" rgba=".9 .9 .9 1" mass="0.001" fluidshape="ellipsoid"/>
                        <geom name="tail2" type="box" pos="0.016 0 0" size="0.0075 0.0015 0.045" rgba=".5 .7 .9 1" density="1250" fluidshape="ellipsoid"/>
                        <site name="marker6" pos="0.016 0 0.05" size="0.005" material="marker"/>

                        <geom name="tail2left" type="box" pos="0.0205 -0.01575 0" size="0.003 0.01425 0.007" rgba=".5 .7 .9 1" density="1250" fluidshape="ellipsoid"/>
                        <geom name="tail2right" type="box" pos="0.0205 0.01575 0" size="0.003 0.01425 0.007" rgba=".5 .7 .9 1" density="1250" fluidshape="ellipsoid"/>
                        <site name="tail2left" pos="0.0205 -0.025 0" size="0.004" rgba=".9 .6 .5 .5"/>
                        <site name="tail2right" pos="0.0205 0.025 0" size="0.004" rgba=".9 .6 .5 .5"/>

                        <geom name="tail2-joint3" type="box" pos="0.027 0 0" size="0.0035 0.0005 0.03" rgba=".9 .9 .9 1" mass="0.001" fluidshape="ellipsoid"/>


                        <body pos="0.0305 0 0">
                            <geom name="joint3" type="cylinder" pos="0 0 0" size="0.002 0.0301" rgba=".9 .2 .2 1" mass="0"/>
                            <joint name="joint3"/>
                            <geom name="joint3-tail3" type="box" pos="0.0035 0 0" size="0.0035 0.0005 0.03" rgba=".9 .9 .9 1" mass="0.001" fluidshape="ellipsoid"/>
                            <geom name="tail3" type="box" pos="0.014499999999999999 0 0" size="0.0075 0.0015 0.0425" rgba=".5 .7 .9 1" density="1250" fluidshape="ellipsoid"/>
                            <site name="marker7" pos="0.014499999999999999 0 0.05" size="0.005" material="marker"/>

                            <geom name="tail3left" type="box" pos="0.019 -0.01075 0" size="0.003 0.00925 0.007" rgba=".5 .7 .9 1" density="1250" fluidshape="ellipsoid"/>
                            <geom name="tail3right" type="box" pos="0.019 0.01075 0" size="0.003 0.00925 0.007" rgba=".5 .7 .9 1" density="1250" fluidshape="ellipsoid"/>
                            <site name="tail3left" pos="0.019 -0.015 0" size="0.004" rgba=".9 .6 .5 .5"/>
                            <site name="tail3right" pos="0.019 0.015 0" size="0.004" rgba=".9 .6 .5 .5"/>

                            <geom name="tail3-joint4" type="box" pos="0.0235 0 0" size="0.0015 0.0005 0.0275" rgba=".9 .9 .9 1" mass="0.001" fluidshape="ellipsoid"/>


                            <body pos="0.024999999999999998 0 0">
                                <geom name="joint4" type="cylinder" pos="0 0 0" size="0.002 0.0276" rgba=".9 .2 .2 1" mass="0"/>
                                <joint name="joint4"/>
                                <geom name="joint4-tail4" type="box" pos="0.0015 0 0" size="0.0015 0.0005 0.0275" rgba=".9 .9 .9 1" mass="0.001" fluidshape="ellipsoid"/>
                                <geom name="tail4" type="box" pos="0.010499999999999999 0 0" size="0.0075 0.0015 0.04" rgba=".5 .7 .9 1" density="1250" fluidshape="ellipsoid"/>
                                <site name="marker8" pos="0.010499999999999999 0 0.05" size="0.005" material="marker"/>

                                <geom name="tail4left" type="box" pos="0.015 -0.00575 0" size="0.003 0.00425 0.007" rgba=".5 .7 .9 1" density="1250" fluidshape="ellipsoid"/>
                                <geom name="tail4right" type="box" pos="0.015 0.00575 0" size="0.003 0.00425 0.007" rgba=".5 .7 .9 1" density="1250" fluidshape="ellipsoid"/>
                                <site name="tail4left" pos="0.015 -0.005 0" size="0.004" rgba=".9 .6 .5 .5"/>
                                <site name="tail4right" pos="0.015 0.005 0" size="0.004" rgba=".9 .6 .5 .5"/>

                                <!-- Tail Fin -->
                                <geom name="tail4-finTail" type="box" pos="0.023 0 0" size="0.005 0.0005 0.0225" rgba=".9 .9 .9 1" mass="0.001" fluidshape="ellipsoid"/>
                                <geom name="finTail" type="mesh" mesh="finTail" pos="0.015999999999999997 0 0" rgba=".9 .2 .2 0.7" mass="0.01" fluidshape="ellipsoid"/>
                                <site name="marker9" pos="0.073 0 0.1" size="0.005" material="marker"/>
                            </body>
                        </body>
                    </body>
                </body>
            </body>


        </body>

    </worldbody>



    <tendon>
        <spatial name="tendonLeft">
            <site site="bodyLeft"/>
            <site site="tail0left"/>
            <site site="tail1left"/>
            <site site="tail2left"/>
            <site site="tail3right"/>
            <site site="tail4right"/>
        </spatial>
        <spatial name="tendonRight">
            <site site="bodyRight"/>
            <site site="tail0right"/>
            <site site="tail1right"/>
            <site site="tail2right"/>
            <site site="tail3left"/>
            <site site="tail4left"/>            
        </spatial>
    </tendon>

    <actuator>
        <!-- <position name="motor" joint="motor" kp="1000" kv="10" ctrllimited="true" ctrlrange="-inf inf" forcerange="-100 100"/> -->
        <velocity name="motor" joint="motor" kv="100" ctrllimited="true" ctrlrange="0 20"/>
    </actuator>

</mujoco>
